Traceback (most recent call last):
  File "mypy\build.py", line 267, in _build
  File "mypy\build.py", line 2886, in dispatch
  File "mypy\build.py", line 3072, in load_graph
  File "mypy\build.py", line 1993, in __init__
  File "mypy\build.py", line 2171, in parse_file
  File "mypy\build.py", line 840, in parse_file
  File "mypy\parse.py", line 27, in parse
  File "mypy\fastparse.py", line 233, in parse
  File "mypy\fastparse.py", line 140, in ast3_parse
  File "C:\Users\Лариса\AppData\Local\Programs\Python\Python310\lib\ast.py", line 50, in parse
    return compile(source, filename, mode, flags,
KeyboardInterrupt

During handling of the above exception, another exception occurred:

Traceback (most recent call last):
  File "C:\Users\Лариса\Desktop\ATB\ATB\venv\lib\site-packages\mypy\__main__.py", line 15, in console_entry
    main()
  File "mypy\main.py", line 127, in main
  File "mypy\main.py", line 211, in run_build
  File "mypy\build.py", line 191, in build
  File "mypy\build.py", line 280, in _build
KeyboardInterrupt

During handling of the above exception, another exception occurred:

Traceback (most recent call last):
  File "C:\Users\Лариса\AppData\Local\Programs\Python\Python310\lib\runpy.py", line 196, in _run_module_as_main
  File "C:\Users\Лариса\AppData\Local\Programs\Python\Python310\lib\runpy.py", line 86, in _run_code
    exec(code, run_globals)
  File "C:\Users\Лариса\Desktop\ATB\ATB\venv\Scripts\mypy.exe\__main__.py", line 7, in <module>
  File "C:\Users\Лариса\Desktop\ATB\ATB\venv\lib\site-packages\mypy\__main__.py", line 15, in console_entry
    main()
KeyboardInterrupt
^C